<?xml version='1.0'?>
<robot name="shady">
	<!-- Base Link -->
	<link name="base_link">
		<visual>
			<origin xyz="0 0 0" rpy="0 0 0" />
			<geometry>
				<box size="0.8 0.5 0.25"/>
			</geometry>
			<material name="blue">
				<color rgba="0 0.7 1 1"/>
			</material>
		</visual>
		<!-- Base collision -->
		<collision>
			<origin xyz="0 0 0" rpy="0 0 0" />
			<geometry>
				<box size="0.8 0.5 0.25"/>
			</geometry>
		</collision>
		<!-- Base Link Inertia-->
		<inertial>
		<mass value="8"/>
			<inertia ixx="0.468" ixy="0.0" ixz="0.0"
			iyy="0.208" iyz="0.0" izz="0.593"/>
		</inertial>
		<!-- Caster -->
		<visual name="caster">
		<origin xyz="0.3 0 -0.125" rpy="0 0 0" />
		<geometry>
			<sphere radius="0.065" />
		</geometry>
		</visual>
		<!-- Caster collision -->
		<collision>
			<origin xyz="0.3 0 -0.125" rpy="0 0 0" />
			<geometry>
			<sphere radius= "0.065" />
			</geometry>
		</collision>
		<!-- Caster Inertia-->
		<inertial>
		<mass value="0.7"/>
			<inertia ixx="0.00118" ixy="0.0" ixz="0.0"
			iyy="0.00118" iyz="0.0" izz="0.00118"/>
		</inertial>
		    
	</link>

	<!-- Right Wheel -->
	<link name="right_wheel">
		<visual>
			<origin xyz="0 0 0" rpy="1.570795 0 0" />
			<geometry>
				<cylinder length="0.1" radius="0.15" />
			</geometry>
			<material name="black">
				<color rgba="0.05 0.05 0.05 1"/>
			</material>
		</visual>
		
		<!-- Right Wheel collision -->
		<collision>
			<origin xyz="0 0 0" rpy="1.570795 0 0" />
			<geometry>
				<cylinder length="0.1" radius="0.15" />
			</geometry>
		</collision>
		<!-- Right Wheel Inertia-->
		<inertial>
			<mass value="0.3"/>
			<inertia ixx="0.003" ixy="0.0" ixz="0.0"
			iyy="0.0019" iyz="0.0" izz="0.0019"/>
		</inertial>
	</link>
	
	<joint name="joint_right_wheel" type="continuous">
		<parent link="base_link"/>
		<child link="right_wheel"/>
		<origin xyz="-0.3 -0.30 -0.07" rpy="0 0 0" />
		<axis xyz="0 1 0" />
	</joint>

	<!-- Left Wheel -->
	<link name="left_wheel">
		<visual>
		<origin xyz="0 0 0" rpy="1.570795 0 0" />
		<geometry>
			<cylinder length="0.1" radius="0.15" />
		</geometry>
		<material name="black"/>
		</visual>
		
	<!-- Left Wheel collision -->
	<collision>
		<origin xyz="0 0 0" rpy="1.570795 0 0" />
		<geometry>
			<cylinder length="0.1" radius="0.15" />
		</geometry>
	</collision>
	<!-- Left Wheel Inertia-->
	<inertial>
		<mass value="0.3"/>
		<inertia ixx="0.003" ixy="0.0" ixz="0.0"
		iyy="0.0019" iyz="0.0" izz="0.0019"/>
	</inertial>
	</link>

	<joint name="joint_left_wheel" type="continuous">
		<parent link="base_link"/>
		<child link="left_wheel"/>
		<origin xyz="-0.3 0.30 -0.07" rpy="0 0 0" />
		<axis xyz="0 1 0" />
	</joint>

	<!-- Gazebo specific color -->
	<gazebo reference="base_link">
		<material>Gazebo/Blue</material>
	</gazebo>
	<gazebo reference="right_wheel">
		<material>Gazebo/Black</material>
	</gazebo>
	<gazebo reference="left_wheel">
		<material>Gazebo/Black</material>
	</gazebo>
	<!-- Gazebo Differential Drive ROS Plugin -->
	<gazebo>
	    <plugin name="differential_drive_controller" filename="libgazebo_ros_diff_drive.so">
		<alwaysOn>true</alwaysOn>
		<updateRate>40</updateRate>
		<legacyMode>false</legacyMode>
		<leftJoint>joint_left_wheel</leftJoint>
		<rightJoint>joint_right_wheel</rightJoint>
		<wheelSeparation>0.60</wheelSeparation>
		<wheelDiameter>0.30</wheelDiameter>
		<torque>5</torque>
		<commandTopic>cmd_vel</commandTopic>
		<odometryTopic>odom</odometryTopic>
		<odometryFrame>odom</odometryFrame>
		<robotBaseFrame>base_link</robotBaseFrame>
		<publishWheelTF>false</publishWheelTF>
		<publishWheelJointState>false</publishWheelJointState>
		<rosDebugLevel>na</rosDebugLevel>
		<wheelAcceleration>0</wheelAcceleration>
		<wheelTorque>5</wheelTorque>
		<odometrySource>world</odometrySource>
		<publishTf>1</publishTf>
	    </plugin>
	</gazebo>

	  <joint name="hokuyo_joint" type="fixed">
	    <axis xyz="0 1 0" />
	    <origin xyz="0.3 0 0.15" rpy="0 0 0"/>
	    <parent link="base_link"/>
	    <child link="hokuyo_link"/>
	  </joint>

	  <!-- Hokuyo Laser -->
	  <link name="hokuyo_link">
	    <collision>
	      <origin xyz="0 0 0" rpy="0 0 0"/>
	      <geometry>
	    <box size="0.1 0.1 0.1"/>
	      </geometry>
	    </collision>

	    <visual>
	      <origin xyz="0 0 0" rpy="0 0 0"/>
	      <geometry>
		<mesh filename="package://shady_description/hokuyo/meshes/hokuyo.dae"/>
	      </geometry>
	    </visual>

	    <inertial>
	      <mass value="1e-5" />
	      <origin xyz="0 0 0" rpy="0 0 0"/>
	      <inertia ixx="1e-6" ixy="0" ixz="0" iyy="1e-6" iyz="0" izz="1e-6" />
	    </inertial>
	  </link>
		  <!-- hokuyo Gazebo plugin -->
		  <gazebo reference="hokuyo_link">
		    <sensor type="gpu_ray" name="head_hokuyo_sensor">
		      <pose>0 0 0 0 0 0</pose>
		      <visualize>true</visualize>
		      <update_rate>40</update_rate>
		      <ray>
			<scan>
			  <horizontal>
			    <samples>720</samples>
			    <resolution>1</resolution>
			    <min_angle>-1.570796</min_angle>
			    <max_angle>1.570796</max_angle>
			  </horizontal>
			</scan>
			<range>
			  <min>0.10</min>
			  <max>30.0</max>
			  <resolution>0.01</resolution>
			</range>
			<noise>
			  <type>gaussian</type>
			  <mean>0.0</mean>
			  <stddev>0.01</stddev>
			</noise>
		      </ray>
		      <plugin name="gazebo_ros_head_hokuyo_controller" filename="libgazebo_ros_gpu_laser.so">
			<topicName>/shady/laser/scan</topicName>
			<frameName>hokuyo_link</frameName>
		      </plugin>
		    </sensor>
		  </gazebo>
</robot>
